{"trial_id": "00", "hyperparameters": {"space": [{"class_name": "Int", "config": {"name": "num_layers", "default": null, "conditions": [], "min_value": 1, "max_value": 5, "step": 1, "sampling": "linear"}}, {"class_name": "Int", "config": {"name": "units_0", "default": null, "conditions": [], "min_value": 8, "max_value": 128, "step": 8, "sampling": "linear"}}, {"class_name": "Choice", "config": {"name": "activation", "default": "relu", "conditions": [], "values": ["relu", "tanh", "sigmoid"], "ordered": false}}, {"class_name": "Float", "config": {"name": "lr", "default": 0.0001, "conditions": [], "min_value": 0.0001, "max_value": 0.01, "step": null, "sampling": "log"}}, {"class_name": "Int", "config": {"name": "units_1", "default": null, "conditions": [], "min_value": 8, "max_value": 128, "step": 8, "sampling": "linear"}}], "values": {"num_layers": 2, "units_0": 24, "activation": "tanh", "lr": 0.0008374645007781961, "units_1": 8}}, "metrics": {"metrics": {}}, "score": null, "best_step": 0, "status": "FAILED", "message": "Traceback (most recent call last):\n  File \"/opt/conda/lib/python3.12/site-packages/keras_tuner/src/engine/base_tuner.py\", line 274, in _try_run_and_update_trial\n    self._run_and_update_trial(trial, *fit_args, **fit_kwargs)\n  File \"/opt/conda/lib/python3.12/site-packages/keras_tuner/src/engine/base_tuner.py\", line 239, in _run_and_update_trial\n    results = self.run_trial(trial, *fit_args, **fit_kwargs)\n              ^^^^^^^^^^^^^^^^^^^^^^^^^^^^^^^^^^^^^^^^^^^^^^\n  File \"/opt/conda/lib/python3.12/site-packages/keras_tuner/src/engine/tuner.py\", line 314, in run_trial\n    obj_value = self._build_and_fit_model(trial, *args, **copied_kwargs)\n                ^^^^^^^^^^^^^^^^^^^^^^^^^^^^^^^^^^^^^^^^^^^^^^^^^^^^^^^^\n  File \"/opt/conda/lib/python3.12/site-packages/keras_tuner/src/engine/tuner.py\", line 233, in _build_and_fit_model\n    results = self.hypermodel.fit(hp, model, *args, **kwargs)\n              ^^^^^^^^^^^^^^^^^^^^^^^^^^^^^^^^^^^^^^^^^^^^^^^\n  File \"/opt/conda/lib/python3.12/site-packages/keras_tuner/src/engine/hypermodel.py\", line 149, in fit\n    return model.fit(*args, **kwargs)\n           ^^^^^^^^^^^^^^^^^^^^^^^^^^\n  File \"/opt/conda/lib/python3.12/site-packages/keras/src/utils/traceback_utils.py\", line 122, in error_handler\n    raise e.with_traceback(filtered_tb) from None\n  File \"/opt/conda/lib/python3.12/site-packages/tensorflow/python/eager/execute.py\", line 59, in quick_execute\n    except TypeError as e:\ntensorflow.python.framework.errors_impl.FailedPreconditionError: Graph execution error:\n\nDetected at node StatefulPartitionedCall defined at (most recent call last):\n  File \"<frozen runpy>\", line 198, in _run_module_as_main\n\n  File \"<frozen runpy>\", line 88, in _run_code\n\n  File \"/opt/conda/lib/python3.12/site-packages/ipykernel_launcher.py\", line 18, in <module>\n\n  File \"/opt/conda/lib/python3.12/site-packages/traitlets/config/application.py\", line 1075, in launch_instance\n\n  File \"/opt/conda/lib/python3.12/site-packages/ipykernel/kernelapp.py\", line 739, in start\n\n  File \"/opt/conda/lib/python3.12/site-packages/tornado/platform/asyncio.py\", line 205, in start\n\n  File \"/opt/conda/lib/python3.12/asyncio/base_events.py\", line 641, in run_forever\n\n  File \"/opt/conda/lib/python3.12/asyncio/base_events.py\", line 1986, in _run_once\n\n  File \"/opt/conda/lib/python3.12/asyncio/events.py\", line 88, in _run\n\n  File \"/opt/conda/lib/python3.12/site-packages/ipykernel/kernelbase.py\", line 545, in dispatch_queue\n\n  File \"/opt/conda/lib/python3.12/site-packages/ipykernel/kernelbase.py\", line 534, in process_one\n\n  File \"/opt/conda/lib/python3.12/site-packages/ipykernel/kernelbase.py\", line 437, in dispatch_shell\n\n  File \"/opt/conda/lib/python3.12/site-packages/ipykernel/ipkernel.py\", line 362, in execute_request\n\n  File \"/opt/conda/lib/python3.12/site-packages/ipykernel/kernelbase.py\", line 778, in execute_request\n\n  File \"/opt/conda/lib/python3.12/site-packages/ipykernel/ipkernel.py\", line 449, in do_execute\n\n  File \"/opt/conda/lib/python3.12/site-packages/ipykernel/zmqshell.py\", line 549, in run_cell\n\n  File \"/opt/conda/lib/python3.12/site-packages/IPython/core/interactiveshell.py\", line 3075, in run_cell\n\n  File \"/opt/conda/lib/python3.12/site-packages/IPython/core/interactiveshell.py\", line 3130, in _run_cell\n\n  File \"/opt/conda/lib/python3.12/site-packages/IPython/core/async_helpers.py\", line 128, in _pseudo_sync_runner\n\n  File \"/opt/conda/lib/python3.12/site-packages/IPython/core/interactiveshell.py\", line 3334, in run_cell_async\n\n  File \"/opt/conda/lib/python3.12/site-packages/IPython/core/interactiveshell.py\", line 3517, in run_ast_nodes\n\n  File \"/opt/conda/lib/python3.12/site-packages/IPython/core/interactiveshell.py\", line 3577, in run_code\n\n  File \"/tmp/ipykernel_21603/3022856722.py\", line 32, in <module>\n\n  File \"/opt/conda/lib/python3.12/site-packages/keras_tuner/src/engine/base_tuner.py\", line 234, in search\n\n  File \"/opt/conda/lib/python3.12/site-packages/keras_tuner/src/engine/base_tuner.py\", line 274, in _try_run_and_update_trial\n\n  File \"/opt/conda/lib/python3.12/site-packages/keras_tuner/src/engine/base_tuner.py\", line 239, in _run_and_update_trial\n\n  File \"/opt/conda/lib/python3.12/site-packages/keras_tuner/src/engine/tuner.py\", line 314, in run_trial\n\n  File \"/opt/conda/lib/python3.12/site-packages/keras_tuner/src/engine/tuner.py\", line 233, in _build_and_fit_model\n\n  File \"/opt/conda/lib/python3.12/site-packages/keras_tuner/src/engine/hypermodel.py\", line 149, in fit\n\n  File \"/opt/conda/lib/python3.12/site-packages/keras/src/utils/traceback_utils.py\", line 117, in error_handler\n\n  File \"/opt/conda/lib/python3.12/site-packages/keras/src/backend/tensorflow/trainer.py\", line 371, in fit\n\n  File \"/opt/conda/lib/python3.12/site-packages/keras/src/backend/tensorflow/trainer.py\", line 219, in function\n\n  File \"/opt/conda/lib/python3.12/site-packages/keras/src/backend/tensorflow/trainer.py\", line 132, in multi_step_on_iterator\n\nDNN library initialization failed. Look at the errors above for more details.\n\t [[{{node StatefulPartitionedCall}}]] [Op:__inference_multi_step_on_iterator_1479]\n"}